Workbook

Sheet Cover
A1: LAPORAN SURVEI MASYARAKAT DESA MERTASARI
A2: 255 respons | 30 Juni–19 Agustus 2026 | PermenPANRB Nomor 14 Tahun 2017
A4: ISI LAPORAN
A5: Ringkasan | B5: Dashboard, profil, rekomendasi, dan temuan prioritas.
A6: SKM Layanan | B6: Penghitungan 9 unsur layanan L–T.
A7: Antikorupsi | B7: Analisis perilaku antikorupsi U–AC.
A8: Pemahaman | B8: Identifikasi pemahaman umum AD–AQ.
A9: Rencana Aksi | B9: Program, waktu, PIC, dan indikator keberhasilan.
A10: Respons Survei | B10: 255 jawaban sumber.
A12: METODE DAN SUMBER
A13: SKM layanan menggunakan skala 1–4, bobot sama untuk 9 unsur, dan konversi ×25. Antikorupsi dan pemahaman umum merupakan analisis komplementer; indikator kanal informasi/pengaduan dianalisis sebagai frekuensi. Sumber resmi: https://peraturan.bpk.go.id/Details/132600/permen-pan-rb-no-14-tahun-2017 dan JDIH Kementerian PANRB.
A18: CARA MEMBACA LAPORAN
A19: 1. Mulai dari Ringkasan | B19: Lihat empat indikator utama, temuan prioritas, profil responden, dan pesan singkat untuk pimpinan.
A20: 2. Baca SKM Layanan | B20: Nilai 25–100 menunjukkan mutu sembilan unsur layanan. Unsur dengan nilai terendah menjadi prioritas perbaikan.
A21: 3. Baca Antikorupsi | B21: Nilai tinggi berarti masyarakat lebih tegas menolak perilaku yang berisiko korupsi. Bagian ini bersifat diagnostik tambahan.
A22: 4. Baca Pemahaman | B22: Bagian ini menunjukkan seberapa jauh warga mengetahui standar, APBDes, pembangunan, dan berpartisipasi dalam RKP Desa.
A23: 5. Gunakan Rencana Aksi | B23: Setiap masalah telah diterjemahkan menjadi kegiatan, target, waktu, penanggung jawab, bukti, dan mekanisme evaluasi.
A25: PESAN UTAMA
A26: Secara umum pelayanan Desa Mertasari dinilai baik, dengan IKM 83,02. Biaya/tarif menjadi kekuatan paling nyata, sedangkan pengelolaan pengaduan, waktu penyelesaian, dan konsistensi hasil layanan masih perlu diperbaiki. Tantangan terbesar justru berada pada keterlibatan warga dalam RKP Desa dan pemahaman APBDes. Oleh karena itu, tindak lanjut tidak cukup hanya memperbaiki loket pelayanan, tetapi juga harus memperkuat transparansi, partisipasi, dan pendidikan integritas.

Sheet Ringkasan
A1: RINGKASAN EKSEKUTIF SURVEI DESA MERTASARI
A2: 255 responden | 30 Juni–19 Agustus 2026
A4: INDIKATOR UTAMA
A5: IKM LAYANAN | C5: ANTIKORUPSI | E5: PEMAHAMAN | G5: REKOMENDASI
A6: ='SKM Layanan'!F17 -> 83.017429 | C6: =Antikorupsi!F17 -> 82.581699 | E6: =Pemahaman!F20 -> 73.74183 | G6: =AVERAGE(Table1[Seberapa puas Anda dengan Pelayanan yang diberikan oleh Pemerintah Desa Mertasari?]) -> 8.3921569
A9: CERITA SINGKAT
A10: ="IKM layanan "&TEXT(A6,"0.00")&" ("&'SKM Layanan'!G17&"/"&'SKM Layanan'!H17&"). Kekuatan utama adalah biaya/tarif. Prioritas layanan: pengaduan, waktu penyelesaian, dan produk. Pemahaman umum "&TEXT(E6,"0.00")&" terutama tertahan oleh partisipasi RKP Desa dan pengetahuan APBDes." -> IKM layanan 83.02 (B/Baik). Kekuatan utama adalah biaya/tarif. Prioritas layanan: pengaduan, waktu penyelesaian, dan produk. Pemahaman umum 73.74 terutama tertahan oleh partisipasi RKP Desa dan pengetahuan APBDes.
A15: TEMUAN PRIORITAS
A16: Temuan | B16: Nilai | C16: Status | D16: Arah | F16: Profil | G16: Jumlah
A17: Penanganan Pengaduan | B17: ='SKM Layanan'!F14 -> 79.411765 | C17: Prioritas | D17: Kanal & SLA | F17: Laki-Laki | G17: =COUNTIF(Table1[Jenis Kelamin],"Laki-Laki") -> 134
A18: Waktu Penyelesaian | B18: ='SKM Layanan'!F8 -> 80.294118 | C18: Prioritas | D18: Standar waktu | F18: Perempuan | G18: =COUNTIF(Table1[Jenis Kelamin],"Perempuan") -> 121
A19: Produk Spesifikasi | B19: ='SKM Layanan'!F10 -> 80.490196 | C19: Prioritas | D19: Checklist | F19: Usia 17–35 | G19: =COUNTIF(Table1[Usia],"17 - 35 Tahun") -> 90
A20: Partisipasi RKP Desa | B20: =Pemahaman!F16 -> 52.54902 | C20: Kritis | D20: Forum inklusif | F20: Usia 36–55 | G20: =COUNTIF(Table1[Usia],"36 - 55 Tahun") -> 130
A21: Pengetahuan APBDes | B21: =Pemahaman!F15 -> 67.745098 | C21: Perlu diperkuat | D21: Publikasi | F21: Usia >55 | G21: {=SUMPRODUCT(--(Table1[Usia]="> 55 Tahun"))} -> 24
A22: Pendapatan tambahan keluarga tak dijelaskan | B22: =Antikorupsi!F6 -> 77.352941 | C22: Fokus edukasi | D22: Integritas | F22: Komentar terisi | G22: =COUNTA(Table1[Saran dan Kritik untuk perbaikan layanan publik Pemerintah Desa Mertasari]) -> 216
A24: UMPAN BALIK
A25: 216 komentar terisi. Tema dominan: mempertahankan pelayanan yang sudah baik (106) dan peningkatan umum (67); masukan spesifik menyebut keramahan/kesopanan (11) dan kecepatan (9). Tema dapat saling tumpang tindih.
A31: Indeks | B31: Nilai
A32: SKM Layanan | B32: =A6 -> 83.017429
A33: Antikorupsi | B33: =C6 -> 82.581699
A34: Pemahaman | B34: =E6 -> 73.74183
A53: NARASI EKSEKUTIF UNTUK PENGAMBIL KEPUTUSAN
A54: Kesimpulan umum | B54: IKM 83,02 menempatkan kinerja pelayanan dalam mutu B atau Baik. Artinya, pengalaman masyarakat pada umumnya positif, tetapi masih terdapat celah operasional yang perlu ditutup agar layanan bergerak menuju kategori Sangat Baik.
A55: Kekuatan utama | B55: Biaya/tarif memperoleh 96,57 atau Sangat Baik. Sebanyak 223 dari 255 responden menyatakan layanan gratis. Kekuatan ini harus dijaga melalui informasi tarif yang terlihat jelas dan larangan pungutan di luar ketentuan.
A56: Prioritas layanan | B56: Penanganan pengaduan 79,41, waktu penyelesaian 80,29, dan produk layanan 80,49 merupakan tiga unsur terendah. Nilainya tetap Baik, namun paling berpotensi menahan peningkatan IKM keseluruhan.
A57: Tantangan tata kelola | B57: Partisipasi RKP Desa hanya 52,55 dan pengetahuan APBDes 67,75. Ini menunjukkan jarak antara pelayanan administratif yang dinilai baik dengan keterlibatan warga dalam proses perencanaan dan pengawasan desa.
A58: Integritas | B58: Indeks antikorupsi 82,58 menunjukkan penolakan masyarakat cukup baik, tetapi pemahaman mengenai pendapatan tambahan yang tidak jelas, nepotisme pelayanan, dan penggunaan kendaraan dinas perlu dipertegas melalui contoh konkret.
A59: Arah kebijakan | B59: Fokus 12 bulan pertama adalah pembenahan pengaduan, kepastian waktu, kendali mutu dokumen, forum RKP yang inklusif, dan publikasi APBDes. Edukasi integritas dan penguatan siklus SKM dilaksanakan berkelanjutan.
A61: BATASAN INTERPRETASI
A62: Survei menggambarkan pendapat 255 responden pada periode 30 Juni–19 Agustus 2026. Nilai antikorupsi dan pemahaman umum adalah indeks diagnostik yang disusun dari pertanyaan tambahan, bukan bagian dari sembilan unsur baku IKM PermenPANRB. Perbandingan dengan periode sebelumnya belum dapat dilakukan karena data pembanding tidak tersedia pada buku kerja ini. Beberapa kelompok berjumlah kecil, sehingga pembacaan per kelompok perlu dilakukan secara hati-hati.

Sheet SKM Layanan
A1: SURVEI KEPUASAN MASYARAKAT — LAYANAN
A2: 9 unsur L–T | Bobot sama | Konversi NRR × 25 | N=255
A4: HASIL PER UNSUR
A5: No | B5: Unsur | C5: Kolom | D5: N | E5: NRR 1–4 | F5: Nilai 25–100 | G5: Kinerja | H5: Peringkat | I5: Arah | J5: Catatan
A6: 1 | B6: Persyaratan | C6: L | D6: =COUNTA(Table1[Apakah persyaratan pengajuan pelayanan yang ada pada Kantor Desa Mertasari telah mempermudah Anda?]) -> 255 | E6: =(COUNTIF(Table1[Apakah persyaratan pengajuan pelayanan yang ada pada Kantor Desa Mertasari telah mempermudah Anda?],"Cukup Mudah")*2+COUNTIF(Table1[Apakah persyaratan pengajuan pelayanan yang ada pada Kantor Desa Mertasari telah mempermudah Anda?],"Mudah")*3+COUNTIF(Table1[Apakah persyaratan pengajuan pelayanan yang ada pada Kantor Desa Mertasari telah mempermudah Anda?],"Sangat Mudah")*4)/COUNTA(Table1[Apakah persyaratan pengajuan pelayanan yang ada pada Kantor Desa Mertasari telah mempermudah Anda?]) -> 3.2901961 | F6: =E6*25 -> 82.254902 | G6: =IF(F6<65,"Tidak Baik",IF(F6<=76.6,"Kurang Baik",IF(F6<=88.3,"Baik","Sangat Baik"))) -> Baik | H6: =_xlfn.RANK.EQ(F6,$F$6:$F$14,1) -> 6 | I6: =IF(H6<=3,"Prioritas","Pertahankan") -> Pertahankan | J6: =IF(F6<65,"D",IF(F6<=76.6,"C",IF(F6<=88.3,"B","A"))) -> B
A7: 2 | B7: Prosedur | C7: M | D7: =COUNTA(Table1[Seberapa mudahkan prosedur pelayanan yang ada di Desa Mertasari untuk setiap pengajuan permohonan layanan?]) -> 255 | E7: =(COUNTIF(Table1[Seberapa mudahkan prosedur pelayanan yang ada di Desa Mertasari untuk setiap pengajuan permohonan layanan?],"Cukup Mudah")*2+COUNTIF(Table1[Seberapa mudahkan prosedur pelayanan yang ada di Desa Mertasari untuk setiap pengajuan permohonan layanan?],"Mudah")*3+COUNTIF(Table1[Seberapa mudahkan prosedur pelayanan yang ada di Desa Mertasari untuk setiap pengajuan permohonan layanan?],"Sangat Mudah")*4)/COUNTA(Table1[Seberapa mudahkan prosedur pelayanan yang ada di Desa Mertasari untuk setiap pengajuan permohonan layanan?]) -> 3.2509804 | F7: =E7*25 -> 81.27451 | G7: =IF(F7<65,"Tidak Baik",IF(F7<=76.6,"Kurang Baik",IF(F7<=88.3,"Baik","Sangat Baik"))) -> Baik | H7: =_xlfn.RANK.EQ(F7,$F$6:$F$14,1) -> 4 | I7: =IF(H7<=3,"Prioritas","Pertahankan") -> Pertahankan | J7: =IF(F7<65,"D",IF(F7<=76.6,"C",IF(F7<=88.3,"B","A"))) -> B
A8: 3 | B8: Waktu Penyelesaian | C8: N | D8: =COUNTA(Table1[Seberapa cepat waktu yang dibutuhkan dalam proses layanan yang diberikan oleh petugas di Kantor Desa Mertasari?]) -> 255 | E8: =(COUNTIF(Table1[Seberapa cepat waktu yang dibutuhkan dalam proses layanan yang diberikan oleh petugas di Kantor Desa Mertasari?],"Kurang Cepat")*2+COUNTIF(Table1[Seberapa cepat waktu yang dibutuhkan dalam proses layanan yang diberikan oleh petugas di Kantor Desa Mertasari?],"Cepat")*3+COUNTIF(Table1[Seberapa cepat waktu yang dibutuhkan dalam proses layanan yang diberikan oleh petugas di Kantor Desa Mertasari?],"Sangat Cepat")*4)/COUNTA(Table1[Seberapa cepat waktu yang dibutuhkan dalam proses layanan yang diberikan oleh petugas di Kantor Desa Mertasari?]) -> 3.2117647 | F8: =E8*25 -> 80.294118 | G8: =IF(F8<65,"Tidak Baik",IF(F8<=76.6,"Kurang Baik",IF(F8<=88.3,"Baik","Sangat Baik"))) -> Baik | H8: =_xlfn.RANK.EQ(F8,$F$6:$F$14,1) -> 2 | I8: =IF(H8<=3,"Prioritas","Pertahankan") -> Prioritas | J8: =IF(F8<65,"D",IF(F8<=76.6,"C",IF(F8<=88.3,"B","A"))) -> B
A9: 4 | B9: Biaya/Tarif | C9: O | D9: =COUNTA(Table1[Menurut Anda, berapa tarif/biaya layanan yang diterapkan atas layanan yang diberikan oleh Pemerintah Desa Mertasari?]) -> 255 | E9: =(COUNTIF(Table1[Menurut Anda, berapa tarif/biaya layanan yang diterapkan atas layanan yang diberikan oleh Pemerintah Desa Mertasari?],"Cukup Mahal")*2+COUNTIF(Table1[Menurut Anda, berapa tarif/biaya layanan yang diterapkan atas layanan yang diberikan oleh Pemerintah Desa Mertasari?],"Murah")*3+COUNTIF(Table1[Menurut Anda, berapa tarif/biaya layanan yang diterapkan atas layanan yang diberikan oleh Pemerintah Desa Mertasari?],"Gratis")*4)/COUNTA(Table1[Menurut Anda, berapa tarif/biaya layanan yang diterapkan atas layanan yang diberikan oleh Pemerintah Desa Mertasari?]) -> 3.8627451 | F9: =E9*25 -> 96.568627 | G9: =IF(F9<65,"Tidak Baik",IF(F9<=76.6,"Kurang Baik",IF(F9<=88.3,"Baik","Sangat Baik"))) -> Sangat Baik | H9: =_xlfn.RANK.EQ(F9,$F$6:$F$14,1) -> 9 | I9: =IF(H9<=3,"Prioritas","Pertahankan") -> Pertahankan | J9: =IF(F9<65,"D",IF(F9<=76.6,"C",IF(F9<=88.3,"B","A"))) -> A
A10: 5 | B10: Produk Spesifikasi | C10: P | D10: =COUNTA(Table1[Bagaimana pendapat saudara tentang kesesuaian produk pelayanan antara yang tercantum dalam standar hasil pelayanan dengan hasil yang diberikan?]) -> 255 | E10: =(COUNTIF(Table1[Bagaimana pendapat saudara tentang kesesuaian produk pelayanan antara yang tercantum dalam standar hasil pelayanan dengan hasil yang diberikan?],"Tidak Sesuai")*1+COUNTIF(Table1[Bagaimana pendapat saudara tentang kesesuaian produk pelayanan antara yang tercantum dalam standar hasil pelayanan dengan hasil yang diberikan?],"Sesuai")*3+COUNTIF(Table1[Bagaimana pendapat saudara tentang kesesuaian produk pelayanan antara yang tercantum dalam standar hasil pelayanan dengan hasil yang diberikan?],"Sangat Sesuai")*4)/COUNTA(Table1[Bagaimana pendapat saudara tentang kesesuaian produk pelayanan antara yang tercantum dalam standar hasil pelayanan dengan hasil yang diberikan?]) -> 3.2196078 | F10: =E10*25 -> 80.490196 | G10: =IF(F10<65,"Tidak Baik",IF(F10<=76.6,"Kurang Baik",IF(F10<=88.3,"Baik","Sangat Baik"))) -> Baik | H10: =_xlfn.RANK.EQ(F10,$F$6:$F$14,1) -> 3 | I10: =IF(H10<=3,"Prioritas","Pertahankan") -> Prioritas | J10: =IF(F10<65,"D",IF(F10<=76.6,"C",IF(F10<=88.3,"B","A"))) -> B
A11: 6 | B11: Kompetensi Pelaksana | C11: Q | D11: =COUNTA(Table1[Bagaimana pendapat Anda tentang kemampuan perangkat desa dalam memberikan penjelasan mengenai prosedur layanan?]) -> 255 | E11: =(COUNTIF(Table1[Bagaimana pendapat Anda tentang kemampuan perangkat desa dalam memberikan penjelasan mengenai prosedur layanan?],"Tidak Jelas")*1+COUNTIF(Table1[Bagaimana pendapat Anda tentang kemampuan perangkat desa dalam memberikan penjelasan mengenai prosedur layanan?],"Kurang Jelas")*2+COUNTIF(Table1[Bagaimana pendapat Anda tentang kemampuan perangkat desa dalam memberikan penjelasan mengenai prosedur layanan?],"Jelas")*3+COUNTIF(Table1[Bagaimana pendapat Anda tentang kemampuan perangkat desa dalam memberikan penjelasan mengenai prosedur layanan?],"Sangat Jelas")*4)/COUNTA(Table1[Bagaimana pendapat Anda tentang kemampuan perangkat desa dalam memberikan penjelasan mengenai prosedur layanan?]) -> 3.2666667 | F11: =E11*25 -> 81.666667 | G11: =IF(F11<65,"Tidak Baik",IF(F11<=76.6,"Kurang Baik",IF(F11<=88.3,"Baik","Sangat Baik"))) -> Baik | H11: =_xlfn.RANK.EQ(F11,$F$6:$F$14,1) -> 5 | I11: =IF(H11<=3,"Prioritas","Pertahankan") -> Pertahankan | J11: =IF(F11<65,"D",IF(F11<=76.6,"C",IF(F11<=88.3,"B","A"))) -> B
A12: 7 | B12: Perilaku Pelaksana | C12: R | D12: =COUNTA(Table1[Bagaimana pendapat Anda tentang kesopanan dan keramahan perangkat desa dalam memberikan layanan?]) -> 255 | E12: =(COUNTIF(Table1[Bagaimana pendapat Anda tentang kesopanan dan keramahan perangkat desa dalam memberikan layanan?],"Sopan dan Ramah")*3+COUNTIF(Table1[Bagaimana pendapat Anda tentang kesopanan dan keramahan perangkat desa dalam memberikan layanan?],"Sangat Sopan dan Sangat Ramah")*4)/COUNTA(Table1[Bagaimana pendapat Anda tentang kesopanan dan keramahan perangkat desa dalam memberikan layanan?]) -> 3.3098039 | F12: =E12*25 -> 82.745098 | G12: =IF(F12<65,"Tidak Baik",IF(F12<=76.6,"Kurang Baik",IF(F12<=88.3,"Baik","Sangat Baik"))) -> Baik | H12: =_xlfn.RANK.EQ(F12,$F$6:$F$14,1) -> 8 | I12: =IF(H12<=3,"Prioritas","Pertahankan") -> Pertahankan | J12: =IF(F12<65,"D",IF(F12<=76.6,"C",IF(F12<=88.3,"B","A"))) -> B
A13: 8 | B13: Sarana Prasarana | C13: S | D13: =COUNTA(Table1[Menurut Anda, apakah telah tersedia sarana prasarana (komputer, jaringan internet dan lainnya) yang mendukung efektivitas dan efisiensi pelayanan di Pemerintah Desa Mertasari?]) -> 255 | E13: =(COUNTIF(Table1[Menurut Anda, apakah telah tersedia sarana prasarana (komputer, jaringan internet dan lainnya) yang mendukung efektivitas dan efisiensi pelayanan di Pemerintah Desa Mertasari?],"Cukup tersedia tapi kurang mendukung")*2+COUNTIF(Table1[Menurut Anda, apakah telah tersedia sarana prasarana (komputer, jaringan internet dan lainnya) yang mendukung efektivitas dan efisiensi pelayanan di Pemerintah Desa Mertasari?],"Tersedia dan mendukung")*3+COUNTIF(Table1[Menurut Anda, apakah telah tersedia sarana prasarana (komputer, jaringan internet dan lainnya) yang mendukung efektivitas dan efisiensi pelayanan di Pemerintah Desa Mertasari?],"Tersedia dan sangat mendukung")*4)/COUNTA(Table1[Menurut Anda, apakah telah tersedia sarana prasarana (komputer, jaringan internet dan lainnya) yang mendukung efektivitas dan efisiensi pelayanan di Pemerintah Desa Mertasari?]) -> 3.2980392 | F13: =E13*25 -> 82.45098 | G13: =IF(F13<65,"Tidak Baik",IF(F13<=76.6,"Kurang Baik",IF(F13<=88.3,"Baik","Sangat Baik"))) -> Baik | H13: =_xlfn.RANK.EQ(F13,$F$6:$F$14,1) -> 7 | I13: =IF(H13<=3,"Prioritas","Pertahankan") -> Pertahankan | J13: =IF(F13<65,"D",IF(F13<=76.6,"C",IF(F13<=88.3,"B","A"))) -> B
A14: 9 | B14: Penanganan Pengaduan | C14: T | D14: =COUNTA(Table1[Bagaimana pendapat Anda tentang ketersediaan dan penanganan layanan pengaduan masyarakat?]) -> 255 | E14: =(COUNTIF(Table1[Bagaimana pendapat Anda tentang ketersediaan dan penanganan layanan pengaduan masyarakat?],"Ada tetapi belum dikelola dengan baik")*2+COUNTIF(Table1[Bagaimana pendapat Anda tentang ketersediaan dan penanganan layanan pengaduan masyarakat?],"Ada dan sudah dikelola dengan cukup baik")*3+COUNTIF(Table1[Bagaimana pendapat Anda tentang ketersediaan dan penanganan layanan pengaduan masyarakat?],"Ada dan sudah dikelola dengan sangat baik")*4)/COUNTA(Table1[Bagaimana pendapat Anda tentang ketersediaan dan penanganan layanan pengaduan masyarakat?]) -> 3.1764706 | F14: =E14*25 -> 79.411765 | G14: =IF(F14<65,"Tidak Baik",IF(F14<=76.6,"Kurang Baik",IF(F14<=88.3,"Baik","Sangat Baik"))) -> Baik | H14: =_xlfn.RANK.EQ(F14,$F$6:$F$14,1) -> 1 | I14: =IF(H14<=3,"Prioritas","Pertahankan") -> Prioritas | J14: =IF(F14<65,"D",IF(F14<=76.6,"C",IF(F14<=88.3,"B","A"))) -> B
B17: IKM UNIT PELAYANAN | F17: =AVERAGE(E6:E14)*25 -> 83.017429 | G17: =IF(F17<65,"D",IF(F17<=76.6,"C",IF(F17<=88.3,"B","A"))) -> B | H17: =IF(F17<65,"Tidak Baik",IF(F17<=76.6,"Kurang Baik",IF(F17<=88.3,"Baik","Sangat Baik"))) -> Baik
A19: Interval: 25,00–64,99 D/Tidak Baik; 65,00–76,60 C/Kurang Baik; 76,61–88,30 B/Baik; 88,31–100 A/Sangat Baik.
A40: PENJELASAN HASIL LAYANAN
A41: Makna nilai 83,02 | B41: Masyarakat menilai layanan sudah baik. Untuk mencapai kategori A/Sangat Baik, nilai perlu melewati 88,30; peningkatan harus diarahkan pada unsur dengan nilai terendah, bukan hanya mempertahankan rata-rata.
A42: Biaya/Tarif — 96,57 | B42: Ini merupakan unsur terbaik. Persepsi gratis atau murah sangat kuat. Pemerintah desa perlu terus memasang informasi tarif resmi dan menyediakan mekanisme pelaporan apabila terdapat permintaan biaya yang tidak sesuai.
A43: Pengaduan — 79,41 | B43: Sebanyak 23 responden menilai pengaduan ada tetapi belum dikelola dengan baik. Masalah utama bukan sekadar ketersediaan kanal, melainkan pencatatan, batas waktu respons, tindak lanjut, dan informasi hasil penyelesaian.
A44: Waktu — 80,29 | B44: Enam responden menyatakan proses kurang cepat. Nilai ini menunjukkan perlunya standar waktu per jenis layanan, pencatatan waktu mulai–selesai, dan analisis kasus yang melewati target.
A45: Produk — 80,49 | B45: Dua responden menyatakan hasil tidak sesuai. Walaupun jumlahnya kecil, kesalahan dokumen memiliki dampak langsung. Pemeriksaan akhir dan checklist perlu diterapkan sebelum dokumen diserahkan.
A46: Unsur lain | B46: Persyaratan, prosedur, kompetensi, perilaku petugas, dan sarana berada pada kategori Baik. Unsur tersebut dipertahankan sambil memperjelas informasi, meningkatkan keramahan, dan memastikan sarana selalu berfungsi.
A48: REKOMENDASI LAYANAN
A49: Prioritas pertama adalah membangun pengelolaan pengaduan satu pintu: tetapkan nomor WA/SMS resmi, tetap pertahankan kotak pengaduan, gunakan nomor tiket/register, tetapkan waktu respons dan penyelesaian, serta umumkan rekap tindak lanjut tanpa membuka identitas pelapor. Prioritas kedua adalah menetapkan standar waktu setiap jenis surat dan memantau penyimpangannya setiap minggu. Prioritas ketiga adalah menerapkan checklist persyaratan dan pemeriksaan akhir dokumen. Biaya/tarif harus dipertahankan melalui papan informasi “gratis/tarif resmi” yang mudah terlihat.
A55: ANALISIS MENDALAM RESPONDEN DENGAN SKOR LAYANAN RENDAH
A56: Definisi analisis: responden dikategorikan memiliki skor rendah apabila memberikan sedikitnya satu jawaban bernilai 1 atau 2 pada sembilan unsur layanan. Dari 255 responden, 59 orang (23,1%) masuk kelompok ini. Kelompok yang lebih berat—rata-rata skor layanan di bawah 3—berjumlah 25 orang (9,8%). Analisis ini membaca pola dan tidak menyimpulkan sebab-akibat; kelompok kecil dan jenis layanan yang dapat dipilih lebih dari satu harus ditafsirkan dengan hati-hati.
A61: Indikator | B61: Skor rendah (1–2) | C61: Persentase | D61: Makna
A62: Prosedur | B62: 31 | C62: 0.1216 | D62: Masih dinilai cukup mudah, belum sepenuhnya sederhana.
A63: Persyaratan | B63: 24 | C63: 0.0941 | D63: Persyaratan belum terasa mudah bagi sebagian pemohon.
A64: Pengaduan | B64: 23 | C64: 0.0902 | D64: Kanal ada, tetapi pengelolaan/tindak lanjut belum meyakinkan.
A65: Sarana | B65: 10 | C65: 0.0392 | D65: Sarana tersedia namun belum cukup mendukung.
A66: Kompetensi | B66: 7 | C66: 0.0275 | D66: Penjelasan petugas kurang/tidak jelas.
A67: Waktu | B67: 6 | C67: 0.0235 | D67: Proses dirasakan kurang cepat.
A68: Biaya/Tarif | B68: 3 | C68: 0.0118 | D68: Sebagian kecil masih menilai cukup mahal.
A69: Produk | B69: 2 | C69: 0.0078 | D69: Dua responden menyatakan hasil tidak sesuai.
A70: Perilaku petugas | B70: 0 | C70: 0 | D70: Tidak ada jawaban rendah; keramahan menjadi kekuatan.
A72: KETERKAITAN DENGAN PROFIL, JENIS LAYANAN, DAN HASIL LAIN
A73: Dampak pada kepuasan | B73: Rata-rata rekomendasi kelompok skor rendah adalah 7,76, lebih rendah dari seluruh responden 8,39. Pada kelompok berat, rekomendasi turun menjadi 6,84 dan 8 dari 25 orang memberi skor rekomendasi ≤6. Pola ini konsisten dengan adanya hambatan operasional, tetapi penyebabnya tetap perlu dikonfirmasi melalui wawancara singkat dan data proses layanan.
A74: Keterkaitan pemahaman | B74: Kelompok skor layanan rendah juga memiliki indeks pemahaman rata-rata 67,41, di bawah indeks keseluruhan 73,74. Sebanyak 56 dari 59 orang juga memiliki sedikitnya satu skor pemahaman rendah. Temuan ini menunjukkan perlunya menguji apakah informasi persyaratan, alur, dan waktu layanan sudah cukup mudah dipahami.
A75: Keterkaitan antikorupsi | B75: Indeks antikorupsi kelompok ini 77,87, lebih rendah dari keseluruhan 82,58; 31 orang juga memiliki skor antikorupsi rendah. Namun hubungan ini tidak otomatis berarti pengalaman korupsi—lebih tepat dibaca sebagai kebutuhan komunikasi integritas dan standar pelayanan yang konsisten.
...

Sheet Antikorupsi
A1: PERSEPSI PERILAKU ANTIKORUPSI
A2: U–AC | Skor tinggi = penolakan lebih tegas | Indeks komplementer
A4: HASIL 9 INDIKATOR
A5: No | B5: Indikator ringkas | C5: Kolom | D5: N | E5: NRR 1–4 | F5: Indeks | G5: Kategori | H5: Peringkat | I5: Arah | J5: Catatan
A6: 1 | B6: Pendapatan tambahan keluarga yang tidak dijelaskan | C6: U | D6: =COUNTA(Table1[Bagaimana pendapat Saudara tentang perilaku Sikap kita terhadap seseorang yang menerima uang tambahan dari pasangan (suami/istri) di luar gaji/penghasilan yang biasa diterima, tanpa mempertanyakan...]) -> 255 | E6: =(COUNTIF(Table1[Bagaimana pendapat Saudara tentang perilaku Sikap kita terhadap seseorang yang menerima uang tambahan dari pasangan (suami/istri) di luar gaji/penghasilan yang biasa diterima, tanpa mempertanyakan...],"Wajar")*1+COUNTIF(Table1[Bagaimana pendapat Saudara tentang perilaku Sikap kita terhadap seseorang yang menerima uang tambahan dari pasangan (suami/istri) di luar gaji/penghasilan yang biasa diterima, tanpa mempertanyakan...],"Cenderung Wajar")*2+COUNTIF(Table1[Bagaimana pendapat Saudara tentang perilaku Sikap kita terhadap seseorang yang menerima uang tambahan dari pasangan (suami/istri) di luar gaji/penghasilan yang biasa diterima, tanpa mempertanyakan...],"Cenderung Tidak Wajar")*3+COUNTIF(Table1[Bagaimana pendapat Saudara tentang perilaku Sikap kita terhadap seseorang yang menerima uang tambahan dari pasangan (suami/istri) di luar gaji/penghasilan yang biasa diterima, tanpa mempertanyakan...],"Tidak Wajar")*4)/COUNTA(Table1[Bagaimana pendapat Saudara tentang perilaku Sikap kita terhadap seseorang yang menerima uang tambahan dari pasangan (suami/istri) di luar gaji/penghasilan yang biasa diterima, tanpa mempertanyakan...]) -> 3.0941176 | F6: =E6*25 -> 77.352941 | G6: =IF(F6<65,"Tidak Baik",IF(F6<=76.6,"Kurang Baik",IF(F6<=88.3,"Baik","Sangat Baik"))) -> Baik | H6: =_xlfn.RANK.EQ(F6,$F$6:$F$14,1) -> 1 | I6: =IF(H6<=3,"Prioritas","Pertahankan") -> Prioritas | J6: Fokus edukasi
A7: 2 | B7: Kendaraan dinas untuk pribadi | C7: V | D7: =COUNTA(Table1[Bagaimana pendapat Saudara tentang perilaku Seorang Perangkat Desa menggunakan kendaraan dinas untuk keperluan keluarga / pribadi.?]) -> 255 | E7: =(COUNTIF(Table1[Bagaimana pendapat Saudara tentang perilaku Seorang Perangkat Desa menggunakan kendaraan dinas untuk keperluan keluarga / pribadi.?],"Wajar")*1+COUNTIF(Table1[Bagaimana pendapat Saudara tentang perilaku Seorang Perangkat Desa menggunakan kendaraan dinas untuk keperluan keluarga / pribadi.?],"Cenderung Wajar")*2+COUNTIF(Table1[Bagaimana pendapat Saudara tentang perilaku Seorang Perangkat Desa menggunakan kendaraan dinas untuk keperluan keluarga / pribadi.?],"Cenderung Tidak Wajar")*3+COUNTIF(Table1[Bagaimana pendapat Saudara tentang perilaku Seorang Perangkat Desa menggunakan kendaraan dinas untuk keperluan keluarga / pribadi.?],"Tidak Wajar")*4)/COUNTA(Table1[Bagaimana pendapat Saudara tentang perilaku Seorang Perangkat Desa menggunakan kendaraan dinas untuk keperluan keluarga / pribadi.?]) -> 3.2078431 | F7: =E7*25 -> 80.196078 | G7: =IF(F7<65,"Tidak Baik",IF(F7<=76.6,"Kurang Baik",IF(F7<=88.3,"Baik","Sangat Baik"))) -> Baik | H7: =_xlfn.RANK.EQ(F7,$F$6:$F$14,1) -> 3 | I7: =IF(H7<=3,"Prioritas","Pertahankan") -> Prioritas | J7: Fokus edukasi
A8: 3 | B8: Imbalan politik via keluarga | C8: W | D8: =COUNTA(Table1[Bagaimana pendapat Saudara tentang perilaku Seseorang mengajak anggota keluarga dalam kampanye Pilkades/Pilkada/Pemilu demi mendapatkan lebih banyak imbalan (uang, barang, sembako, pulsa dll).?]) -> 255 | E8: =(COUNTIF(Table1[Bagaimana pendapat Saudara tentang perilaku Seseorang mengajak anggota keluarga dalam kampanye Pilkades/Pilkada/Pemilu demi mendapatkan lebih banyak imbalan (uang, barang, sembako, pulsa dll).?],"Wajar")*1+COUNTIF(Table1[Bagaimana pendapat Saudara tentang perilaku Seseorang mengajak anggota keluarga dalam kampanye Pilkades/Pilkada/Pemilu demi mendapatkan lebih banyak imbalan (uang, barang, sembako, pulsa dll).?],"Cenderung Wajar")*2+COUNTIF(Table1[Bagaimana pendapat Saudara tentang perilaku Seseorang mengajak anggota keluarga dalam kampanye Pilkades/Pilkada/Pemilu demi mendapatkan lebih banyak imbalan (uang, barang, sembako, pulsa dll).?],"Cenderung Tidak Wajar")*3+COUNTIF(Table1[Bagaimana pendapat Saudara tentang perilaku Seseorang mengajak anggota keluarga dalam kampanye Pilkades/Pilkada/Pemilu demi mendapatkan lebih banyak imbalan (uang, barang, sembako, pulsa dll).?],"Tidak Wajar")*4)/COUNTA(Table1[Bagaimana pendapat Saudara tentang perilaku Seseorang mengajak anggota keluarga dalam kampanye Pilkades/Pilkada/Pemilu demi mendapatkan lebih banyak imbalan (uang, barang, sembako, pulsa dll).?]) -> 3.372549 | F8: =E8*25 -> 84.313725 | G8: =IF(F8<65,"Tidak Baik",IF(F8<=76.6,"Kurang Baik",IF(F8<=88.3,"Baik","Sangat Baik"))) -> Baik | H8: =_xlfn.RANK.EQ(F8,$F$6:$F$14,1) -> 7 | I8: =IF(H8<=3,"Prioritas","Pertahankan") -> Pertahankan | J8: Pemeliharaan
A9: 4 | B9: Nepotisme pelayanan | C9: X | D9: =COUNTA(Table1[Bagaimana pendapat Saudara tentang perilaku Seseorang memanfaatkan hubungan keluarga yang mempunyai kewenangan agar dipermudah dalam pelayanan publik.?]) -> 255 | E9: =(COUNTIF(Table1[Bagaimana pendapat Saudara tentang perilaku Seseorang memanfaatkan hubungan keluarga yang mempunyai kewenangan agar dipermudah dalam pelayanan publik.?],"Wajar")*1+COUNTIF(Table1[Bagaimana pendapat Saudara tentang perilaku Seseorang memanfaatkan hubungan keluarga yang mempunyai kewenangan agar dipermudah dalam pelayanan publik.?],"Cenderung Wajar")*2+COUNTIF(Table1[Bagaimana pendapat Saudara tentang perilaku Seseorang memanfaatkan hubungan keluarga yang mempunyai kewenangan agar dipermudah dalam pelayanan publik.?],"Cenderung Tidak Wajar")*3+COUNTIF(Table1[Bagaimana pendapat Saudara tentang perilaku Seseorang memanfaatkan hubungan keluarga yang mempunyai kewenangan agar dipermudah dalam pelayanan publik.?],"Tidak Wajar")*4)/COUNTA(Table1[Bagaimana pendapat Saudara tentang perilaku Seseorang memanfaatkan hubungan keluarga yang mempunyai kewenangan agar dipermudah dalam pelayanan publik.?]) -> 3.2039216 | F9: =E9*25 -> 80.098039 | G9: =IF(F9<65,"Tidak Baik",IF(F9<=76.6,"Kurang Baik",IF(F9<=88.3,"Baik","Sangat Baik"))) -> Baik | H9: =_xlfn.RANK.EQ(F9,$F$6:$F$14,1) -> 2 | I9: =IF(H9<=3,"Prioritas","Pertahankan") -> Prioritas | J9: Fokus edukasi
A10: 5 | B10: Gaya hidup di luar kemampuan | C10: Y | D10: =COUNTA(Table1[Bagaimana pendapat Saudara tentang perilaku Seseorang bergaya hidup mewah di luar dari kemampuan agar diakui/dianggap berada oleh masyarkat.?]) -> 255 | E10: =(COUNTIF(Table1[Bagaimana pendapat Saudara tentang perilaku Seseorang bergaya hidup mewah di luar dari kemampuan agar diakui/dianggap berada oleh masyarkat.?],"Wajar")*1+COUNTIF(Table1[Bagaimana pendapat Saudara tentang perilaku Seseorang bergaya hidup mewah di luar dari kemampuan agar diakui/dianggap berada oleh masyarkat.?],"Cenderung Wajar")*2+COUNTIF(Table1[Bagaimana pendapat Saudara tentang perilaku Seseorang bergaya hidup mewah di luar dari kemampuan agar diakui/dianggap berada oleh masyarkat.?],"Cenderung Tidak Wajar")*3+COUNTIF(Table1[Bagaimana pendapat Saudara tentang perilaku Seseorang bergaya hidup mewah di luar dari kemampuan agar diakui/dianggap berada oleh masyarkat.?],"Tidak Wajar")*4)/COUNTA(Table1[Bagaimana pendapat Saudara tentang perilaku Seseorang bergaya hidup mewah di luar dari kemampuan agar diakui/dianggap berada oleh masyarkat.?]) -> 3.545098 | F10: =E10*25 -> 88.627451 | G10: =IF(F10<65,"Tidak Baik",IF(F10<=76.6,"Kurang Baik",IF(F10<=88.3,"Baik","Sangat Baik"))) -> Sangat Baik | H10: =_xlfn.RANK.EQ(F10,$F$6:$F$14,1) -> 9 | I10: =IF(H10<=3,"Prioritas","Pertahankan") -> Pertahankan | J10: Pemeliharaan
A11: 6 | B11: Pemberian berlebih saat hajatan | C11: Z | D11: =COUNTA(Table1[Bagaimana pendapat Saudara tentang perilaku Suatu keluarga memberi uang/barang/fasilitas yang lebih kepada Pejabat atau Perangkat Desa ketika melaksanakan hajatan (penikahan, khitanan, kematian dl...]) -> 255 | E11: =(COUNTIF(Table1[Bagaimana pendapat Saudara tentang perilaku Suatu keluarga memberi uang/barang/fasilitas yang lebih kepada Pejabat atau Perangkat Desa ketika melaksanakan hajatan (penikahan, khitanan, kematian dl...],"Wajar")*1+COUNTIF(Table1[Bagaimana pendapat Saudara tentang perilaku Suatu keluarga memberi uang/barang/fasilitas yang lebih kepada Pejabat atau Perangkat Desa ketika melaksanakan hajatan (penikahan, khitanan, kematian dl...],"Cenderung Wajar")*2+COUNTIF(Table1[Bagaimana pendapat Saudara tentang perilaku Suatu keluarga memberi uang/barang/fasilitas yang lebih kepada Pejabat atau Perangkat Desa ketika melaksanakan hajatan (penikahan, khitanan, kematian dl...],"Cenderung Tidak Wajar")*3+COUNTIF(Table1[Bagaimana pendapat Saudara tentang perilaku Suatu keluarga memberi uang/barang/fasilitas yang lebih kepada Pejabat atau Perangkat Desa ketika melaksanakan hajatan (penikahan, khitanan, kematian dl...],"Tidak Wajar")*4)/COUNTA(Table1[Bagaimana pendapat Saudara tentang perilaku Suatu keluarga memberi uang/barang/fasilitas yang lebih kepada Pejabat atau Perangkat Desa ketika melaksanakan hajatan (penikahan, khitanan, kematian dl...]) -> 3.2235294 | F11: =E11*25 -> 80.588235 | G11: =IF(F11<65,"Tidak Baik",IF(F11<=76.6,"Kurang Baik",IF(F11<=88.3,"Baik","Sangat Baik"))) -> Baik | H11: =_xlfn.RANK.EQ(F11,$F$6:$F$14,1) -> 4 | I11: =IF(H11<=3,"Prioritas","Pertahankan") -> Pertahankan | J11: Pemeliharaan
A12: 7 | B12: RT/RW membagikan imbalan | C12: AA | D12: =COUNTA(Table1[Bagaimana pendapat Saudara tentang perilaku Ketua RT / RW membantu calon Kepala Desa/Kepala Daerah/Legislatif untuk membagikan uang/barang/fasilitas kepada Masyarakat agar dipilih.?]) -> 255 | E12: =(COUNTIF(Table1[Bagaimana pendapat Saudara tentang perilaku Ketua RT / RW membantu calon Kepala Desa/Kepala Daerah/Legislatif untuk membagikan uang/barang/fasilitas kepada Masyarakat agar dipilih.?],"Wajar")*1+COUNTIF(Table1[Bagaimana pendapat Saudara tentang perilaku Ketua RT / RW membantu calon Kepala Desa/Kepala Daerah/Legislatif untuk membagikan uang/barang/fasilitas kepada Masyarakat agar dipilih.?],"Cenderung Wajar")*2+COUNTIF(Table1[Bagaimana pendapat Saudara tentang perilaku Ketua RT / RW membantu calon Kepala Desa/Kepala Daerah/Legislatif untuk membagikan uang/barang/fasilitas kepada Masyarakat agar dipilih.?],"Cenderung Tidak Wajar")*3+COUNTIF(Table1[Bagaimana pendapat Saudara tentang perilaku Ketua RT / RW membantu calon Kepala Desa/Kepala Daerah/Legislatif untuk membagikan uang/barang/fasilitas kepada Masyarakat agar dipilih.?],"Tidak Wajar")*4)/COUNTA(Table1[Bagaimana pendapat Saudara tentang perilaku Ketua RT / RW membantu calon Kepala Desa/Kepala Daerah/Legislatif untuk membagikan uang/barang/fasilitas kepada Masyarakat agar dipilih.?]) -> 3.3411765 | F12: =E12*25 -> 83.529412 | G12: =IF(F12<65,"Tidak Baik",IF(F12<=76.6,"Kurang Baik",IF(F12<=88.3,"Baik","Sangat Baik"))) -> Baik | H12: =_xlfn.RANK.EQ(F12,$F$6:$F$14,1) -> 5 | I12: =IF(H12<=3,"Prioritas","Pertahankan") -> Pertahankan | J12: Pemeliharaan
A13: 8 | B13: Bantuan tanpa cek asal-usul | C13: AB | D13: =COUNTA(Table1[Bagaimana pendapat Saudara tentang perilaku Kelompok/Lembaga Masyarakat menerima sumbangan/bantuan/pemberian/hibah dari seseorang tanpa mempertanyakan asal usulnya.?]) -> 255 | E13: =(COUNTIF(Table1[Bagaimana pendapat Saudara tentang perilaku Kelompok/Lembaga Masyarakat menerima sumbangan/bantuan/pemberian/hibah dari seseorang tanpa mempertanyakan asal usulnya.?],"Wajar")*1+COUNTIF(Table1[Bagaimana pendapat Saudara tentang perilaku Kelompok/Lembaga Masyarakat menerima sumbangan/bantuan/pemberian/hibah dari seseorang tanpa mempertanyakan asal usulnya.?],"Cenderung Wajar")*2+COUNTIF(Table1[Bagaimana pendapat Saudara tentang perilaku Kelompok/Lembaga Masyarakat menerima sumbangan/bantuan/pemberian/hibah dari seseorang tanpa mempertanyakan asal usulnya.?],"Cenderung Tidak Wajar")*3+COUNTIF(Table1[Bagaimana pendapat Saudara tentang perilaku Kelompok/Lembaga Masyarakat menerima sumbangan/bantuan/pemberian/hibah dari seseorang tanpa mempertanyakan asal usulnya.?],"Tidak Wajar")*4)/COUNTA(Table1[Bagaimana pendapat Saudara tentang perilaku Kelompok/Lembaga Masyarakat menerima sumbangan/bantuan/pemberian/hibah dari seseorang tanpa mempertanyakan asal usulnya.?]) -> 3.3843137 | F13: =E13*25 -> 84.607843 | G13: =IF(F13<65,"Tidak Baik",IF(F13<=76.6,"Kurang Baik",IF(F13<=88.3,"Baik","Sangat Baik"))) -> Baik | H13: =_xlfn.RANK.EQ(F13,$F$6:$F$14,1) -> 8 | I13: =IF(H13<=3,"Prioritas","Pertahankan") -> Pertahankan | J13: Pemeliharaan
A14: 9 | B14: Bansos tidak sesuai kriteria | C14: AC | D14: =COUNTA(Table1[Bagaimana pendapat Saudara tentang perilaku Ketua RT/RW/Kepala Desa mengusulkan warganya yang tidak sesuai kriteria untuk mendapatkan dana bantuan sosial.?]) -> 255 | E14: =(COUNTIF(Table1[Bagaimana pendapat Saudara tentang perilaku Ketua RT/RW/Kepala Desa mengusulkan warganya yang tidak sesuai kriteria untuk mendapatkan dana bantuan sosial.?],"Wajar")*1+COUNTIF(Table1[Bagaimana pendapat Saudara tentang perilaku Ketua RT/RW/Kepala Desa mengusulkan warganya yang tidak sesuai kriteria untuk mendapatkan dana bantuan sosial.?],"Cenderung Wajar")*2+COUNTIF(Table1[Bagaimana pendapat Saudara tentang perilaku Ketua RT/RW/Kepala Desa mengusulkan warganya yang tidak sesuai kriteria untuk mendapatkan dana bantuan sosial.?],"Cenderung Tidak Wajar")*3+COUNTIF(Table1[Bagaimana pendapat Saudara tentang perilaku Ketua RT/RW/Kepala Desa mengusulkan warganya yang tidak sesuai kriteria untuk mendapatkan dana bantuan sosial.?],"Tidak Wajar")*4)/COUNTA(Table1[Bagaimana pendapat Saudara tentang perilaku Ketua RT/RW/Kepala Desa mengusulkan warganya yang tidak sesuai kriteria untuk mendapatkan dana bantuan sosial.?]) -> 3.3568627 | F14: =E14*25 -> 83.921569 | G14: =IF(F14<65,"Tidak Baik",IF(F14<=76.6,"Kurang Baik",IF(F14<=88.3,"Baik","Sangat Baik"))) -> Baik | H14: =_xlfn.RANK.EQ(F14,$F$6:$F$14,1) -> 6 | I14: =IF(H14<=3,"Prioritas","Pertahankan") -> Pertahankan | J14: Pemeliharaan
B17: INDEKS PERSEPSI ANTIKORUPSI | F17: =AVERAGE(E6:E14)*25 -> 82.581699 | G17: Bukan unsur baku IKM
A39: PENJELASAN PERSEPSI ANTIKORUPSI
A40: Makna indeks 82,58 | B40: Secara umum masyarakat cukup tegas menolak perilaku yang berisiko korupsi. Namun nilai ini belum berarti risiko telah hilang; fokusnya adalah memperjelas situasi yang masih dianggap abu-abu.
A41: Pendapatan tambahan keluarga — 77,35 | B41: Sebanyak 70 responden masih menilai wajar atau cenderung wajar apabila seseorang menerima tambahan uang keluarga di luar penghasilan biasa tanpa menanyakan sumbernya. Ini bukan dasar untuk menuduh, tetapi menunjukkan perlunya literasi mengenai kewajaran sumber penghasilan dan pengelolaan risiko konflik kepentingan.
A42: Nepotisme — 80,10 | B42: Sebanyak 53 responden menilai penggunaan hubungan keluarga untuk kemudahan pelayanan wajar atau cenderung wajar. Standar antrean dan persyaratan harus berlaku sama bagi semua warga.
A43: Kendaraan dinas — 80,20 | B43: Sebanyak 52 responden menilai penggunaan kendaraan dinas untuk keluarga/pribadi wajar atau cenderung wajar. Aturan penggunaan aset perlu dibuat sederhana, tertulis, dan diawasi.
A44: Kekuatan — 88,63 | B44: Penolakan terhadap gaya hidup mewah di luar kemampuan merupakan indikator terkuat. Pesan ini dapat menjadi pintu masuk kampanye integritas yang mudah dipahami masyarakat.
A45: Prinsip tindak lanjut | B45: Gunakan contoh kasus sehari-hari, bukan istilah hukum yang rumit. Bedakan gratifikasi, konflik kepentingan, penyalahgunaan aset, nepotisme, dan politik uang beserta kanal konsultasi/pelaporannya.
A47: REKOMENDASI ANTIKORUPSI
A48: Laksanakan kelas singkat integritas minimal setiap semester untuk perangkat desa, RT/RW, BPD, tokoh masyarakat, kelompok perempuan, dan pemuda. Materinya mencakup konflik kepentingan, penggunaan aset dinas, penerimaan hadiah, bansos, politik uang, serta cara menolak dan melaporkan secara aman. Seluruh aparatur menandatangani pakta integritas, penggunaan aset dicatat, dan kasus konflik kepentingan dideklarasikan. Efektivitas program diukur melalui survei ulang terhadap tiga indikator terendah dan pencatatan tindak lanjut pengaduan integritas.
A55: ANALISIS MENDALAM RESPONDEN DENGAN SKOR ANTIKORUPSI RENDAH
A56: Skor rendah berarti responden menjawab “Wajar” atau “Cenderung Wajar” pada sedikitnya satu perilaku berisiko. Terdapat 104 orang (40,8%) dalam kelompok ini; 53 orang (20,8%) memiliki rata-rata indeks antikorupsi di bawah 75. Besarnya kelompok tidak langsung menunjukkan adanya praktik korupsi, melainkan memperlihatkan perilaku yang batas kewajarannya belum dipahami secara seragam.
A61: Perilaku | B61: Wajar/cenderung wajar | C61: Persentase | D61: Risiko interpretasi
A62: Pendapatan tambahan tak jelas | B62: 70 | C62: 0.2745 | D62: Sumber pendapatan tidak biasa belum selalu dianggap perlu dipertanyakan.
A63: Pemberian berlebih saat hajatan | B63: 54 | C63: 0.2118 | D63: Batas antara tradisi, hadiah, dan konflik kepentingan belum jelas.
A64: Nepotisme pelayanan | B64: 53 | C64: 0.2078 | D64: Kemudahan karena hubungan keluarga masih ditoleransi sebagian warga.
A65: Kendaraan dinas untuk pribadi | B65: 52 | C65: 0.2039 | D65: Penggunaan aset publik untuk kepentingan pribadi belum tegas dipahami.
A66: RT/RW membagikan imbalan | B66: 42 | C66: 0.1647 | D66: Risiko politik uang masih dianggap wajar oleh sebagian responden.
A67: Imbalan politik via keluarga | B67: 40 | C67: 0.1569 | D67: Keterlibatan keluarga tidak menghilangkan unsur imbalan politik.
A68: Bansos tidak sesuai kriteria | B68: 38 | C68: 0.149 | D68: Penyimpangan sasaran bantuan belum ditolak seragam.
A69: Bantuan tanpa cek asal-usul | B69: 32 | C69: 0.1255 | D69: Uji asal-usul bantuan belum menjadi kebiasaan.
A70: Gaya hidup di luar kemampuan | B70: 20 | C70: 0.0784 | D70: Indikator paling dipahami; tetap perlu dipertahankan.
A72: KETERKAITAN DENGAN KEPUASAN, PROFIL, DAN PEMAHAMAN
A73: Bukan terutama masalah kepuasan | B73: Kelompok dengan skor antikorupsi rendah tetap memiliki IKM layanan 82,37 dan rekomendasi 8,60. Karena kepuasan layanan tetap tinggi, skor ini lebih tepat dibaca sebagai perbedaan pemahaman mengenai batas perilaku yang wajar—bukan sebagai bukti terjadinya korupsi atau pengalaman langsung responden.
A74: Keterkaitan pemahaman | B74: Indeks pemahaman kelompok ini 72,08; 85 dari 104 orang juga memiliki minimal satu skor pemahaman rendah. Edukasi integritas harus dikaitkan dengan SOP, APBDes, bantuan sosial, aset desa, dan partisipasi—bukan berdiri sebagai slogan umum.
A75: Gender dan usia | B75: Proporsi perempuan 53/121 (43,8%) dan laki-laki 51/134 (38,1%) relatif berdekatan. Usia 36–55 memiliki proporsi 58/130 (44,6%). Perbedaannya tidak cukup untuk menjadikan satu kelompok sebagai sasaran tunggal.
A76: Pendidikan | B76: D4/S1/S2 menunjukkan 14 dari 22 orang (63,6%), lebih tinggi daripada kelompok lain, tetapi sampelnya kecil. Ini menunjukkan masalah bukan semata rendahnya pendidikan; perilaku seperti hadiah, hubungan keluarga, dan penggunaan aset memang dapat dipersepsikan berbeda secara sosial.
...

Sheet Pemahaman
A1: IDENTIFIKASI PEMAHAMAN UMUM MASYARAKAT
A2: Kolom AD–AQ | 12 indikator ordinal dan 2 kanal informasi | Analisis diagnostik, bukan unsur baku IKM
A4: PEMAHAMAN DAN PARTISIPASI
A5: No | B5: Indikator | C5: Kolom | D5: N | E5: NRR 1–4 | F5: Indeks 25–100 | G5: Kategori | H5: Peringkat | I5: Arah | J5: Interpretasi
A6: 1 | B6: Integritas perangkat | C6: AD | D6: =COUNTA(Table1[Apakah Perangkat Desa Mertasari dalam memberikan pelayanan menerapkan prinsip berintegritas dan berperilaku sesuai etika?]) -> 255 | E6: =(COUNTIF(Table1[Apakah Perangkat Desa Mertasari dalam memberikan pelayanan menerapkan prinsip berintegritas dan berperilaku sesuai etika?],"Tidak Pernah")*1+COUNTIF(Table1[Apakah Perangkat Desa Mertasari dalam memberikan pelayanan menerapkan prinsip berintegritas dan berperilaku sesuai etika?],"Kadang-Kadang")*2+COUNTIF(Table1[Apakah Perangkat Desa Mertasari dalam memberikan pelayanan menerapkan prinsip berintegritas dan berperilaku sesuai etika?],"Pernah")*3+COUNTIF(Table1[Apakah Perangkat Desa Mertasari dalam memberikan pelayanan menerapkan prinsip berintegritas dan berperilaku sesuai etika?],"Selalu")*4)/COUNTA(Table1[Apakah Perangkat Desa Mertasari dalam memberikan pelayanan menerapkan prinsip berintegritas dan berperilaku sesuai etika?]) -> 3.6823529 | F6: =E6*25 -> 92.058824 | G6: =IF(F6<65,"Tidak Baik",IF(F6<=76.6,"Kurang Baik",IF(F6<=88.3,"Baik","Sangat Baik"))) -> Sangat Baik | H6: =_xlfn.RANK.EQ(F6,$F$6:$F$17,1) -> 12 | I6: =IF(H6<=3,"Prioritas",IF(F6<76.61,"Perlu diperkuat","Pertahankan")) -> Pertahankan | J6: =IF(F6<65,"Kritis",IF(F6<76.61,"Belum merata","Memadai")) -> Memadai
A7: 2 | B7: Sosialisasi antikorupsi | C7: AE | D7: =COUNTA(Table1[Apakah Anda pernah mengetahui adanya sosialisasi antikorupsi di Desa Mertasari?]) -> 255 | E7: =(COUNTIF(Table1[Apakah Anda pernah mengetahui adanya sosialisasi antikorupsi di Desa Mertasari?],"Tidak Pernah")*1+COUNTIF(Table1[Apakah Anda pernah mengetahui adanya sosialisasi antikorupsi di Desa Mertasari?],"Jarang")*2+COUNTIF(Table1[Apakah Anda pernah mengetahui adanya sosialisasi antikorupsi di Desa Mertasari?],"Sering")*3+COUNTIF(Table1[Apakah Anda pernah mengetahui adanya sosialisasi antikorupsi di Desa Mertasari?],"Sangat Sering")*4)/COUNTA(Table1[Apakah Anda pernah mengetahui adanya sosialisasi antikorupsi di Desa Mertasari?]) -> 2.9803922 | F7: =E7*25 -> 74.509804 | G7: =IF(F7<65,"Tidak Baik",IF(F7<=76.6,"Kurang Baik",IF(F7<=88.3,"Baik","Sangat Baik"))) -> Kurang Baik | H7: =_xlfn.RANK.EQ(F7,$F$6:$F$17,1) -> 9 | I7: =IF(H7<=3,"Prioritas",IF(F7<76.61,"Perlu diperkuat","Pertahankan")) -> Perlu diperkuat | J7: =IF(F7<65,"Kritis",IF(F7<76.61,"Belum merata","Memadai")) -> Belum merata
A8: 3 | B8: Kesediaan menjadi teladan 9 nilai | C8: AF | D8: =COUNTA(Table1[Apakah Anda bersedia memberikan contoh dalam mengimplementasikan 9 nilai antikorupsi dalam kehidupan sehari-hari?]) -> 255 | E8: =(COUNTIF(Table1[Apakah Anda bersedia memberikan contoh dalam mengimplementasikan 9 nilai antikorupsi dalam kehidupan sehari-hari?],"Tidak Bersedia")*1+COUNTIF(Table1[Apakah Anda bersedia memberikan contoh dalam mengimplementasikan 9 nilai antikorupsi dalam kehidupan sehari-hari?],"Ragu-Ragu")*2+COUNTIF(Table1[Apakah Anda bersedia memberikan contoh dalam mengimplementasikan 9 nilai antikorupsi dalam kehidupan sehari-hari?],"Bersedia")*3+COUNTIF(Table1[Apakah Anda bersedia memberikan contoh dalam mengimplementasikan 9 nilai antikorupsi dalam kehidupan sehari-hari?],"Sangat Bersedia")*4)/COUNTA(Table1[Apakah Anda bersedia memberikan contoh dalam mengimplementasikan 9 nilai antikorupsi dalam kehidupan sehari-hari?]) -> 2.9215686 | F8: =E8*25 -> 73.039216 | G8: =IF(F8<65,"Tidak Baik",IF(F8<=76.6,"Kurang Baik",IF(F8<=88.3,"Baik","Sangat Baik"))) -> Kurang Baik | H8: =_xlfn.RANK.EQ(F8,$F$6:$F$17,1) -> 8 | I8: =IF(H8<=3,"Prioritas",IF(F8<76.61,"Perlu diperkuat","Pertahankan")) -> Perlu diperkuat | J8: =IF(F8<65,"Kritis",IF(F8<76.61,"Belum merata","Memadai")) -> Belum merata
A9: 4 | B9: Budaya lokal pencegahan korupsi | C9: AG | D9: =COUNTA(Table1[Apakah Anda mengetahui adanya adat istiadat / budaya yang mendorong upaya pencegahan korupsi di Desa Mertasari?]) -> 255 | E9: =(COUNTIF(Table1[Apakah Anda mengetahui adanya adat istiadat / budaya yang mendorong upaya pencegahan korupsi di Desa Mertasari?],"Tidak Tahu")*1+COUNTIF(Table1[Apakah Anda mengetahui adanya adat istiadat / budaya yang mendorong upaya pencegahan korupsi di Desa Mertasari?],"Kurang Tahu")*2+COUNTIF(Table1[Apakah Anda mengetahui adanya adat istiadat / budaya yang mendorong upaya pencegahan korupsi di Desa Mertasari?],"Tahu")*3+COUNTIF(Table1[Apakah Anda mengetahui adanya adat istiadat / budaya yang mendorong upaya pencegahan korupsi di Desa Mertasari?],"Sangat Tahu")*4)/COUNTA(Table1[Apakah Anda mengetahui adanya adat istiadat / budaya yang mendorong upaya pencegahan korupsi di Desa Mertasari?]) -> 2.8627451 | F9: =E9*25 -> 71.568627 | G9: =IF(F9<65,"Tidak Baik",IF(F9<=76.6,"Kurang Baik",IF(F9<=88.3,"Baik","Sangat Baik"))) -> Kurang Baik | H9: =_xlfn.RANK.EQ(F9,$F$6:$F$17,1) -> 4 | I9: =IF(H9<=3,"Prioritas",IF(F9<76.61,"Perlu diperkuat","Pertahankan")) -> Perlu diperkuat | J9: =IF(F9<65,"Kritis",IF(F9<76.61,"Belum merata","Memadai")) -> Belum merata
A10: 5 | B10: Peran tokoh masyarakat | C10: AH | D10: =COUNTA(Table1[Apakah Anda mengetahui peran Tokoh masyarakat, tokoh agama, tokoh adat, tokoh pemuda dan kaum perempuan dalam mendorong upaya pencegahan korupsi di Desa Mertasari?]) -> 255 | E10: =(COUNTIF(Table1[Apakah Anda mengetahui peran Tokoh masyarakat, tokoh agama, tokoh adat, tokoh pemuda dan kaum perempuan dalam mendorong upaya pencegahan korupsi di Desa Mertasari?],"Tidak Tahu")*1+COUNTIF(Table1[Apakah Anda mengetahui peran Tokoh masyarakat, tokoh agama, tokoh adat, tokoh pemuda dan kaum perempuan dalam mendorong upaya pencegahan korupsi di Desa Mertasari?],"Kurang Tahu")*2+COUNTIF(Table1[Apakah Anda mengetahui peran Tokoh masyarakat, tokoh agama, tokoh adat, tokoh pemuda dan kaum perempuan dalam mendorong upaya pencegahan korupsi di Desa Mertasari?],"Tahu")*3+COUNTIF(Table1[Apakah Anda mengetahui peran Tokoh masyarakat, tokoh agama, tokoh adat, tokoh pemuda dan kaum perempuan dalam mendorong upaya pencegahan korupsi di Desa Mertasari?],"Sangat Tahu")*4)/COUNTA(Table1[Apakah Anda mengetahui peran Tokoh masyarakat, tokoh agama, tokoh adat, tokoh pemuda dan kaum perempuan dalam mendorong upaya pencegahan korupsi di Desa Mertasari?]) -> 2.8862745 | F10: =E10*25 -> 72.156863 | G10: =IF(F10<65,"Tidak Baik",IF(F10<=76.6,"Kurang Baik",IF(F10<=88.3,"Baik","Sangat Baik"))) -> Kurang Baik | H10: =_xlfn.RANK.EQ(F10,$F$6:$F$17,1) -> 5 | I10: =IF(H10<=3,"Prioritas",IF(F10<76.61,"Perlu diperkuat","Pertahankan")) -> Perlu diperkuat | J10: =IF(F10<65,"Kritis",IF(F10<76.61,"Belum merata","Memadai")) -> Belum merata
A11: 6 | B11: Pengetahuan maklumat pelayanan | C11: AI | D11: =COUNTA(Table1[Apakah Anda mengetahui adanya Maklumat Pelayanan di Kantor Desa Mertasari?]) -> 255 | E11: =(COUNTIF(Table1[Apakah Anda mengetahui adanya Maklumat Pelayanan di Kantor Desa Mertasari?],"Tidak Tahu")*1+COUNTIF(Table1[Apakah Anda mengetahui adanya Maklumat Pelayanan di Kantor Desa Mertasari?],"Kurang Tahu")*2+COUNTIF(Table1[Apakah Anda mengetahui adanya Maklumat Pelayanan di Kantor Desa Mertasari?],"Tahu")*3+COUNTIF(Table1[Apakah Anda mengetahui adanya Maklumat Pelayanan di Kantor Desa Mertasari?],"Sangat Tahu")*4)/COUNTA(Table1[Apakah Anda mengetahui adanya Maklumat Pelayanan di Kantor Desa Mertasari?]) -> 2.8901961 | F11: =E11*25 -> 72.254902 | G11: =IF(F11<65,"Tidak Baik",IF(F11<=76.6,"Kurang Baik",IF(F11<=88.3,"Baik","Sangat Baik"))) -> Kurang Baik | H11: =_xlfn.RANK.EQ(F11,$F$6:$F$17,1) -> 7 | I11: =IF(H11<=3,"Prioritas",IF(F11<76.61,"Perlu diperkuat","Pertahankan")) -> Perlu diperkuat | J11: =IF(F11<65,"Kritis",IF(F11<76.61,"Belum merata","Memadai")) -> Belum merata
A12: 7 | B12: Dukungan terhadap maklumat | C12: AJ | D12: =COUNTA(Table1[Apakah Anda sepakat dengan kalimat "Dengan ini, kami menyatakan sanggup menyelenggarakan pelayanan dengan sebaik-baiknya sesuai standar pelayanan yang telah ditetapkan, serta melakukan upaya perba...]) -> 255 | E12: =(COUNTIF(Table1[Apakah Anda sepakat dengan kalimat "Dengan ini, kami menyatakan sanggup menyelenggarakan pelayanan dengan sebaik-baiknya sesuai standar pelayanan yang telah ditetapkan, serta melakukan upaya perba...],"Kurang Setuju")*2+COUNTIF(Table1[Apakah Anda sepakat dengan kalimat "Dengan ini, kami menyatakan sanggup menyelenggarakan pelayanan dengan sebaik-baiknya sesuai standar pelayanan yang telah ditetapkan, serta melakukan upaya perba...],"Setuju")*3+COUNTIF(Table1[Apakah Anda sepakat dengan kalimat "Dengan ini, kami menyatakan sanggup menyelenggarakan pelayanan dengan sebaik-baiknya sesuai standar pelayanan yang telah ditetapkan, serta melakukan upaya perba...],"Sangat Setuju")*4)/COUNTA(Table1[Apakah Anda sepakat dengan kalimat "Dengan ini, kami menyatakan sanggup menyelenggarakan pelayanan dengan sebaik-baiknya sesuai standar pelayanan yang telah ditetapkan, serta melakukan upaya perba...]) -> 3.3764706 | F12: =E12*25 -> 84.411765 | G12: =IF(F12<65,"Tidak Baik",IF(F12<=76.6,"Kurang Baik",IF(F12<=88.3,"Baik","Sangat Baik"))) -> Baik | H12: =_xlfn.RANK.EQ(F12,$F$6:$F$17,1) -> 11 | I12: =IF(H12<=3,"Prioritas",IF(F12<76.61,"Perlu diperkuat","Pertahankan")) -> Pertahankan | J12: =IF(F12<65,"Kritis",IF(F12<76.61,"Belum merata","Memadai")) -> Memadai
A13: 8 | B13: Pengetahuan standar/SOP | C13: AK | D13: =COUNTA(Table1[Apakah Anda mengetahui adanya Standar Pelayanan / SOP Pelayanan di Kantor Desa Mertasari?]) -> 255 | E13: =(COUNTIF(Table1[Apakah Anda mengetahui adanya Standar Pelayanan / SOP Pelayanan di Kantor Desa Mertasari?],"Tidak Tahu")*1+COUNTIF(Table1[Apakah Anda mengetahui adanya Standar Pelayanan / SOP Pelayanan di Kantor Desa Mertasari?],"Kurang Tahu")*2+COUNTIF(Table1[Apakah Anda mengetahui adanya Standar Pelayanan / SOP Pelayanan di Kantor Desa Mertasari?],"Tahu")*3+COUNTIF(Table1[Apakah Anda mengetahui adanya Standar Pelayanan / SOP Pelayanan di Kantor Desa Mertasari?],"Sangat Tahu")*4)/COUNTA(Table1[Apakah Anda mengetahui adanya Standar Pelayanan / SOP Pelayanan di Kantor Desa Mertasari?]) -> 2.8862745 | F13: =E13*25 -> 72.156863 | G13: =IF(F13<65,"Tidak Baik",IF(F13<=76.6,"Kurang Baik",IF(F13<=88.3,"Baik","Sangat Baik"))) -> Kurang Baik | H13: =_xlfn.RANK.EQ(F13,$F$6:$F$17,1) -> 5 | I13: =IF(H13<=3,"Prioritas",IF(F13<76.61,"Perlu diperkuat","Pertahankan")) -> Perlu diperkuat | J13: =IF(F13<65,"Kritis",IF(F13<76.61,"Belum merata","Memadai")) -> Belum merata
A14: 9 | B14: Akses informasi SPM | C14: AM | D14: =COUNTA(Table1[Menurut Anda, apakah informasi mengenai Standar Pelayanan Minimal (kesehatan, pendidikan, sosial, lingkungan, kependudukan, keuangan dan pelayanan lainnya) telah tersedia dan dapat diakes?]) -> 255 | E14: =(COUNTIF(Table1[Menurut Anda, apakah informasi mengenai Standar Pelayanan Minimal (kesehatan, pendidikan, sosial, lingkungan, kependudukan, keuangan dan pelayanan lainnya) telah tersedia dan dapat diakes?],"Tidak Tahu")*1+COUNTIF(Table1[Menurut Anda, apakah informasi mengenai Standar Pelayanan Minimal (kesehatan, pendidikan, sosial, lingkungan, kependudukan, keuangan dan pelayanan lainnya) telah tersedia dan dapat diakes?],"Tidak Tersedia")*1+COUNTIF(Table1[Menurut Anda, apakah informasi mengenai Standar Pelayanan Minimal (kesehatan, pendidikan, sosial, lingkungan, kependudukan, keuangan dan pelayanan lainnya) telah tersedia dan dapat diakes?],"Tersedia tapi tidak dapat diakses")*2+COUNTIF(Table1[Menurut Anda, apakah informasi mengenai Standar Pelayanan Minimal (kesehatan, pendidikan, sosial, lingkungan, kependudukan, keuangan dan pelayanan lainnya) telah tersedia dan dapat diakes?],"Tersedia dan dapat diakses")*4)/COUNTA(Table1[Menurut Anda, apakah informasi mengenai Standar Pelayanan Minimal (kesehatan, pendidikan, sosial, lingkungan, kependudukan, keuangan dan pelayanan lainnya) telah tersedia dan dapat diakes?]) -> 3.3333333 | F14: =E14*25 -> 83.333333 | G14: =IF(F14<65,"Tidak Baik",IF(F14<=76.6,"Kurang Baik",IF(F14<=88.3,"Baik","Sangat Baik"))) -> Baik | H14: =_xlfn.RANK.EQ(F14,$F$6:$F$17,1) -> 10 | I14: =IF(H14<=3,"Prioritas",IF(F14<76.61,"Perlu diperkuat","Pertahankan")) -> Pertahankan | J14: =IF(F14<65,"Kritis",IF(F14<76.61,"Belum merata","Memadai")) -> Memadai
A15: 10 | B15: Pengetahuan APBDes | C15: AO | D15: =COUNTA(Table1[Apakah Anda mengetahui informasi tentang Anggaran Pendapatan dan Belanja Desa Mertasari?]) -> 255 | E15: =(COUNTIF(Table1[Apakah Anda mengetahui informasi tentang Anggaran Pendapatan dan Belanja Desa Mertasari?],"Tidak Tahu")*1+COUNTIF(Table1[Apakah Anda mengetahui informasi tentang Anggaran Pendapatan dan Belanja Desa Mertasari?],"Kurang Tahu")*2+COUNTIF(Table1[Apakah Anda mengetahui informasi tentang Anggaran Pendapatan dan Belanja Desa Mertasari?],"Tahu")*3+COUNTIF(Table1[Apakah Anda mengetahui informasi tentang Anggaran Pendapatan dan Belanja Desa Mertasari?],"Sangat Tahu")*4)/COUNTA(Table1[Apakah Anda mengetahui informasi tentang Anggaran Pendapatan dan Belanja Desa Mertasari?]) -> 2.7098039 | F15: =E15*25 -> 67.745098 | G15: =IF(F15<65,"Tidak Baik",IF(F15<=76.6,"Kurang Baik",IF(F15<=88.3,"Baik","Sangat Baik"))) -> Kurang Baik | H15: =_xlfn.RANK.EQ(F15,$F$6:$F$17,1) -> 2 | I15: =IF(H15<=3,"Prioritas",IF(F15<76.61,"Perlu diperkuat","Pertahankan")) -> Prioritas | J15: =IF(F15<65,"Kritis",IF(F15<76.61,"Belum merata","Memadai")) -> Belum merata
A16: 11 | B16: Partisipasi RKP Desa | C16: AP | D16: =COUNTA(Table1[Apakah Anda terlibat dan berpartisipasi dalam penyusunan Rencana Kerja Pemerintah (RKP) Desa Mertasari?]) -> 255 | E16: =(COUNTIF(Table1[Apakah Anda terlibat dan berpartisipasi dalam penyusunan Rencana Kerja Pemerintah (RKP) Desa Mertasari?],"Tidak Ikut")*1+COUNTIF(Table1[Apakah Anda terlibat dan berpartisipasi dalam penyusunan Rencana Kerja Pemerintah (RKP) Desa Mertasari?],"Kadang-Kadang")*2+COUNTIF(Table1[Apakah Anda terlibat dan berpartisipasi dalam penyusunan Rencana Kerja Pemerintah (RKP) Desa Mertasari?],"Ikut berpartisipasi")*3+COUNTIF(Table1[Apakah Anda terlibat dan berpartisipasi dalam penyusunan Rencana Kerja Pemerintah (RKP) Desa Mertasari?],"Ikut terlibat dan berpartisipasi")*4)/COUNTA(Table1[Apakah Anda terlibat dan berpartisipasi dalam penyusunan Rencana Kerja Pemerintah (RKP) Desa Mertasari?]) -> 2.1019608 | F16: =E16*25 -> 52.54902 | G16: =IF(F16<65,"Tidak Baik",IF(F16<=76.6,"Kurang Baik",IF(F16<=88.3,"Baik","Sangat Baik"))) -> Tidak Baik | H16: =_xlfn.RANK.EQ(F16,$F$6:$F$17,1) -> 1 | I16: =IF(H16<=3,"Prioritas",IF(F16<76.61,"Perlu diperkuat","Pertahankan")) -> Prioritas | J16: =IF(F16<65,"Kritis",IF(F16<76.61,"Belum merata","Memadai")) -> Kritis
A17: 12 | B17: Pengetahuan keterlibatan pembangunan | C17: AQ | D17: =COUNTA(Table1[Apakah Anda mengetahui keterlibatan lembaga desa dan masyarakat dalam kegiatan pembangunan di Desa Mertasari?]) -> 255 | E17: =(COUNTIF(Table1[Apakah Anda mengetahui keterlibatan lembaga desa dan masyarakat dalam kegiatan pembangunan di Desa Mertasari?],"Tidak Tahu")*1+COUNTIF(Table1[Apakah Anda mengetahui keterlibatan lembaga desa dan masyarakat dalam kegiatan pembangunan di Desa Mertasari?],"Kurang Tahu")*2+COUNTIF(Table1[Apakah Anda mengetahui keterlibatan lembaga desa dan masyarakat dalam kegiatan pembangunan di Desa Mertasari?],"Tahu")*3+COUNTIF(Table1[Apakah Anda mengetahui keterlibatan lembaga desa dan masyarakat dalam kegiatan pembangunan di Desa Mertasari?],"Sangat Tahu")*4)/COUNTA(Table1[Apakah Anda mengetahui keterlibatan lembaga desa dan masyarakat dalam kegiatan pembangunan di Desa Mertasari?]) -> 2.7647059 | F17: =E17*25 -> 69.117647 | G17: =IF(F17<65,"Tidak Baik",IF(F17<=76.6,"Kurang Baik",IF(F17<=88.3,"Baik","Sangat Baik"))) -> Kurang Baik | H17: =_xlfn.RANK.EQ(F17,$F$6:$F$17,1) -> 3 | I17: =IF(H17<=3,"Prioritas",IF(F17<76.61,"Perlu diperkuat","Pertahankan")) -> Prioritas | J17: =IF(F17<65,"Kritis",IF(F17<76.61,"Belum merata","Memadai")) -> Belum merata
B20: INDEKS PEMAHAMAN UMUM | F20: =AVERAGE(E6:E17)*25 -> 73.74183 | G20: Indeks diagnostik untuk penentuan program
A22: KANAL INFORMASI DAN PENGADUAN
A23: Sumber informasi SPM | B23: Jumlah | D23: Media pengaduan | E23: Jumlah
A24: Papan pengumuman | B24: =COUNTIF(Table1[Darimanakah anda memperoleh informasi mengenai Standar Pelayanan Minimal (kesehatan, pendidikan, sosial, lingkungan, kependudukan, keuangan dan pelayanan lainnya)?],"Papan Pengumuman (Kantor Desa, Poskampling, Rumah Ketua RT dan tempat strategis lainnya)") -> 107 | D24: WA/SMS | E24: =COUNTIF(Table1[Media Pengaduan Masyarakat apa yang sering Anda gunakan untuk menyampaikan pengaduan kepada Pemerintah Desa Mertasari?],"WA/SMS") -> 110
A25: Papan + media sosial | B25: =COUNTIF(Table1[Darimanakah anda memperoleh informasi mengenai Standar Pelayanan Minimal (kesehatan, pendidikan, sosial, lingkungan, kependudukan, keuangan dan pelayanan lainnya)?],"Papan Pengumuman dan Media Sosial") -> 77 | D25: Kotak pengaduan | E25: =COUNTIF(Table1[Media Pengaduan Masyarakat apa yang sering Anda gunakan untuk menyampaikan pengaduan kepada Pemerintah Desa Mertasari?],"Kotak Pengaduan") -> 99
A26: Website/media sosial | B26: =COUNTIF(Table1[Darimanakah anda memperoleh informasi mengenai Standar Pelayanan Minimal (kesehatan, pendidikan, sosial, lingkungan, kependudukan, keuangan dan pelayanan lainnya)?],"Website Desa / Media Sosial") -> 55 | D26: Website/media sosial | E26: =COUNTIF(Table1[Media Pengaduan Masyarakat apa yang sering Anda gunakan untuk menyampaikan pengaduan kepada Pemerintah Desa Mertasari?],"Website/Media Sosial") -> 31
A27: Tidak tahu | B27: =COUNTIF(Table1[Darimanakah anda memperoleh informasi mengenai Standar Pelayanan Minimal (kesehatan, pendidikan, sosial, lingkungan, kependudukan, keuangan dan pelayanan lainnya)?],"Tidak Tahu") -> 16 | D27: Tidak tahu | E27: =COUNTIF(Table1[Media Pengaduan Masyarakat apa yang sering Anda gunakan untuk menyampaikan pengaduan kepada Pemerintah Desa Mertasari?],"Tidak Tahu") -> 15
A49: PENJELASAN HASIL
A50: Gambaran umum | B50: Indeks 73,74 menunjukkan pemahaman dan partisipasi belum merata. Warga menilai integritas perangkat sangat baik, tetapi pengetahuan tata kelola dan keterlibatan dalam perencanaan masih lebih lemah.
A51: Partisipasi RKP Desa | B51: Nilai 52,55 adalah titik paling kritis: 103 responden tidak ikut dan 45 hanya kadang-kadang. Pemerintah desa perlu mengubah partisipasi dari sekadar undangan menjadi proses yang mudah diakses dan menghasilkan umpan balik.
A52: Pengetahuan APBDes | B52: Nilai 67,75 menunjukkan 71 responden tidak tahu atau kurang tahu. Anggaran perlu diterjemahkan ke informasi sederhana: sumber dana, program utama, nilai belanja, progres, dan manfaat.
A53: Keterlibatan pembangunan | B53: Nilai 69,12 menunjukkan peran lembaga dan warga belum terlihat jelas. Informasi harus menjawab siapa melakukan apa, kapan, hasilnya, dan bagaimana warga mengawasi.
